Workbook

Sheet Personal-Budget_2026
A2: Hoja 1 — CONTROL DE COMPRAS
A4: Título:
A6: Control de Compras y Presupuesto 2026
A8: ID | B8: Producto | C8: Categoría | H8: Prioridad | J8: Tienda | K8: Precio Estimado | L8: Precio Real | M8: Diferencia | N8: Cantidad | O8: Fecha Planeada | P8: Estado | Q8: Método de Pago | R8: Notas
A9: 1 | B9: Laptop | C9: Tecnología | H9: Alta | J9: Amazon | K9: 900 | L9: 1200 | N9: 1 | O9: 46244 | P9: Pendiente | Q9: Tarjeta | R9: Para trabajo
A10: 2 | B10: Escritorio | C10: Oficina | H10: Media | J10: IKEA | K10: 150 | L10: 250 | N10: 1 | O10: 46249 | P10: Pendiente | Q10: Efectivo | R10: Setup
A11: 3 | B11: Monitor | C11: Tecnología | H11: Alta | J11: Amazon | K11: 250 | L11: 275 | N11: 1 | O11: 46254 | P11: Pendiente | Q11: Tarjeta | R11: Programacion
A12: 4 | B12: Lampara | C12: Oficina | H12: Alta | J12: IKEA | K12: 1500 | L12: 1575 | M12: 75 | N12: 1 | O12: 46175 | P12: Completado | Q12: Tarjeta | R12: Setup
A16: Hoja 2 — PRESUPUESTO MENSUAL
A18: Título:
A20: Presupuesto Mensual | N20: Ideas para “Inversión Personal”
A22: Mes | B22: Ingreso Esperado | C22: Gastos Fijos | H22: Gastos Variables | J22: Ahorro | K22: Inversión Personal | L22: Dinero Restante | N22: Aquí pondrás cosas que te ayudan a crecer:
A23: Enero | B23: 0 | C23: 0 | H23: 0 | J23: 0 | K23: 0 | L23: 0
A24: Febrero | B24: 0 | C24: 0 | H24: 0 | J24: 0 | K24: 0 | L24: 0 | N24: Cursos
A25: Marzo | B25: 0 | C25: 0 | H25: 0 | J25: 0 | K25: 0 | L25: 0 | N25: Certificaciones
N26: Libros
N27: PC
N28: Herramientas
N29: Internet
N30: Setup
A33: Hoja 3 — METAS FINANCIERAS
A35: Título:
A37: Metas y Objetivos
A39: Objetivo | B39: Precio Objetivo | C39: Fecha Meta | F39: Prioridad | G39: Estado | H39: Ahorro Actual | J39: Falta
A40: Silla de escritorio | B40: 6500 | C40: 46357 | F40: Alta | G40: En progreso | H40: 100 | J40: 50
A41: Certificación SQL | B41: 120 | C41: 46296 | F41: Alta | G41: Pendiente | H41: 0 | J41: 1250
A42: Setup Oficina | B42: 20000 | C42: 46388 | F42: Media | G42: Pendiente | H42: 50 | J42: 450
A47: Hoja 4 — CONTROL DE AHORROS
A49: Título:
A51: Seguimiento de Ahorros
A53: Fecha | B53: Cantidad Guardada | C53: Motivo | F53: Total Acumulado
A54: 46174 | B54: 850 | C54: Escritorio | F54: 300
A55: 46387 | B55: 0 | C55: Fondo Setup | F55: 50
A60: Hoja 5 — PLAN PROFESIONAL
A62: Esta hoja te ayudará muchísimo porque estás preparándote para trabajar en tecnología.
A64: Título:
A66: Roadmap Profesional
A68: Habilidad | B68: Estado | C68: Nivel | F68: Fecha Inicio | G68: Fecha Objetivo | H68: Fecha Dominio | J68: Recursos
A69: SQL | B69: En progreso | C69: Básico, intermedio | F69: may-15,26 | G69: ago-26,26 | H69: Ene'2027 | J69: Cursos + Claude
A70: GitHub | B70: En progreso | C70: Básico | F70: may-31,26 | G70: jul-26,26 | H70: 46266 | J70: Proyectos,LinkdIn
...

Sheet Junio-2026
A1: Tienda Dominicana
A4: Cantidad | B4: Descripcion | C4: Valor Unitario | D4: Valor Total
A5: 5 | B5: Equipo de Sonido | C5: 9000 | D5: =A5*C5 -> 45000
A6: 3 | B6: Estufa | C6: 2000 | D6: =A6*C6 -> 6000
A7: 4 | B7: Lamparas | C7: 1800 | D7: =A7*C7 -> 7200
A8: 8 | B8: Pantallas | C8: 1350 | D8: =A8*C8 -> 10800
A9: 10 | B9: Inversores | C9: 1000 | D9: =A9*C9 -> 10000
A10: 15 | B10: Sillas | C10: 1500 | D10: =A10*C10 -> 22500
A11: 8 | B11: Puertas | C11: 4000 | D11: =A11*C11 -> 32000
C12: TOTAL | D12: =SUM(D5:D11) -> 133500
A17: Grafico Estadistico
A19: Nombre y Apellido | B19: Dias Trabajados | C19: Sueldo Basico | D19: Total Sueldo
A20: Carlos Almonte | B20: 30 | C20: 2500000 | D20: =C20/30*B20 -> 2500000
A21: Manuela Cirena | B21: 30 | C21: 3500000 | D21: =C21/30*B21 -> 3500000
A22: Carmen Hernandez | B22: 30 | C22: 210000 | D22: =C22/30*B22 -> 210000
A23: Pedro Acosta | B23: 30 | C23: 250000 | D23: =C23/30*B23 -> 250000
A24: Albert Diaz | B24: 30 | C24: 280000 | D24: =C24/30*B24 -> 280000
A25: Eddy Abreu | B25: 30 | C25: 350000 | D25: =C25/30*B25 -> 350000
A26: Thiago Rincon | B26: 30 | C26: 380000 | D26: =C26/30*B26 -> 380000
A27: Francy Ortiz | B27: 30 | C27: 480000 | D27: =C27/30*B27 -> 480000
A28: Fernanda Abreu | B28: 30 | C28: 540000 | D28: =C28/30*B28 -> 540000
A31: Grafico Estadistico
A33: Nombre y Apellido | B33: Dias Trabajados | C33: Sueldo Basico | D33: Total Sueldo
A34: Carlos Almonte | B34: 30 | C34: 3000000 | D34: =C34/30*B34 -> 3000000
A35: Manuela Cirena | B35: 18 | C35: 3500000 | D35: =C35/30*B35 -> 2100000
A36: Carmen Hernandez | B36: 15 | C36: 4000000 | D36: =C36/30*B36 -> 2000000
A37: Pedro Acosta | B37: 10 | C37: 4500000 | D37: =C37/30*B37 -> 1500000
A38: Albert Diaz | B38: 25 | C38: 5000000 | D38: =C38/30*B38 -> 4166666.7
A39: Eddy Abreu | B39: 30 | C39: 5500000 | D39: =C39/30*B39 -> 5500000
A40: Thiago Rincon | B40: 30 | C40: 6500000 | D40: =C40/30*B40 -> 6500000
A41: Francy Ortiz | B41: 25 | C41: 7000000 | D41: =C41/30*B41 -> 5833333.3
A42: Fernanda Abreu | B42: 25 | C42: 7500000 | D42: =C42/30*B42 -> 6250000
A46: Sistemas Unidos
A48: Funcion Si-EXCEL 2013
A50: Nombre | B50: Apellido | C50: Excel | D50: Word | E50: Access | F50: Promedio | G50: Nota Final
A51: Dostin | B51: Hurtado | C51: 5 | D51: 5 | E51: 5 | F51: =AVERAGE(C51:D51:E51) -> 5 | G51: =IF(C51>3,"APROBADO","REPROBADO") -> APROBADO
A52: Sandy | B52: Olivera | C52: 2 | D52: 2 | E52: 4 | F52: =AVERAGE(C52:D52:E52) -> 2.6666667 | G52: =IF(C52>3,"APROBADO","REPROBADO") -> REPROBADO
A53: Juliano | B53: Centurion | C53: 1 | D53: 5 | E53: 4 | F53: =AVERAGE(C53:D53:E53) -> 3.3333333 | G53: =IF(C53>3,"APROBADO","REPROBADO") -> REPROBADO
A54: Fukencio | B54: Martinez | C54: 3 | D54: 2 | E54: 5 | F54: =AVERAGE(C54:D54:E54) -> 3.3333333 | G54: =IF(C54>3,"APROBADO","REPROBADO") -> REPROBADO
A78: Gastos
...

Sheet Junio-30-2026
A2: Gastos
A3: Fecha | B3: Categoria | C3: Descripcion | D3: Monto RD$
A4: JUN 12, 2026 | B4: Salud | C4: Dentista | D4: 1000 | E4: Gasto Normal Controlado
A5: JUN 15, 2026 | B5: Compras online | C5: Temu | D5: 1083 | E5: Gasto Mas Elevado, !Cuidad!
A6: JUN , 29, 2026 | B6: Salidas | C6: Fiestas | D6: 1641.33
A7: JUN 8, 2027 | B7: Salud | C7: Vision | D7: 3800 | E7: Sin Registro Aun
A8: JUN , 2026 | B8: Transporte | C8: Diligencia | D8: 0
A9: JUN 18, 2026 | B9: Utiles de Oficina | C9: Suministro | D9: 510
A10: JUN 20, 2026 | B10: Mini Market | C10: Almuerzo | D10: 15
A11: JUN 18, 2027 | B11: Barber-Shop | C11: Corte | D11: 1400
A12: JUN 25,2026 | B12: Farmacia | C12: Recarga | D12: 230
A13: JUN 29, 2026 | B13: Matthias | C13: Bebe | D13: 1000
A16: Resumen
A17: Categoria | B17: Total RD$
A18: Compras online | B18: =SUMIF($B$4:$B$11,A18,$D$4:$D$11) -> 1083
A19: Transporte | B19: =SUMIF($B$4:$B$11,A19,$D$4:$D$11) -> 0
A20: Salud | B20: =SUMIF($B$4:$B$11,A20,$D$4:$D$11) -> 4800
A21: Salidas | B21: =SUMIF($B$4:$B$13,A21,$D$4:$D$13) -> 1641.33
A22: Utiles de Oficina | B22: =SUMIF($B$4:$B$11,A22,$D$4:$D$11) -> 0
A23: Comida | B23: =SUMIF($B$4:$B$11,A23,$D$4:$D$11) -> 0
A24: Mini Market | B24: =SUMIF($B$4:$B$11,A24,$D$4:$D$11) -> 15
A25: Barber-Shop | B25: =SUMIF($B$4:$B$11,A25,$D$4:$D$11) -> 1400
A26: Matthias | B26: =SUMIF($B$4:$B$13,A26,$D$4:$D$13) -> 1000
A27: Farmacia | B27: =SUMIF($B$4:$B$12,A27,$D$4:$D$12) -> 230
A28: Otros | B28: =SUM(B18:B27) -> 10169.33
A29: Gatos
A30: Mayor Alto Gasto

Sheet Julio-31-2026
A2: Gastos | C2: 46204
A4: Fecha | B4: ID | C4: Categoria | D4: Descripcion | E4: Monto RD$
C5: Salud | D5: Dentista
C6: Compras online | D6: Temu
C7: Salidas | D7: Fiestas
C8: Salud | D8: Vision
C9: Transporte | D9: Diligencia
C10: Utiles de Oficina | D10: Suministro
A11: 46204 | C11: Mini Market | D11: Compras | E11: 220
C12: Barber-Shop | D12: Corte
C13: Farmacia | D13: Recarga
C14: Matthias | D14: Bebe | I14: 15
I15: 15
A16: Categoria | C16: Total RD $ | I16: 55
A17: Mini Market | C17: =SUMIF($C$5:$C$14,$A$17,$E$5:$E$14) -> 220 | I17: =SUM(I14:I16) -> 85
A18: Otros | I18: =+SUM(I14:I17) -> 170
A19: Total Gastos | C19: =SUM(C17:C18) -> 220

Sheet Libros 
B1: Registro de Lectura 2026
A3: # | B3: Libro | C3: Autor | D3: Fecha inicio | E3: Fecha Fin | F3: Dias Invertidos | G3: Estado | H3: Calificacion ⭐ | I3: Total Dias Leyendo | J3: Leccion Principal
A4: 1 | B4: Padre Rico, Padre Pobre | C4: Robert Kiyosaki | D4: 46127 | E4: 46154 | F4: =E4-D4 -> 27 | G4: Done | H4: 4 | I4: =SUM(F4:F6) -> 106
A5: 2 | B5: Habitos Atomicos | C5: James Clear | D5: 46157 | E5: 46203 | F5: =E5-D5 -> 46 | G5: Done | H5: 5 | I5: =AVERAGE(F4:F6) -> 35.333333 | J5: Disciplina, Constancia,Persevrancia,Orden
A6: 3 | B6: Deja de Ser Tu | C6: Joe Dispenza | D6: 46174 | E6: - | F6: =TODAY()-D6 -> 33 | G6: Leyendo | H6: 5 | J6: Dejar de Ser yo de mi pasado, Y crear una nueva identidad
A7: 4 | B7: La Psicologia del Dinero | C7: Morgan Housel | D7: - | E7: - | F7: - | G7: Pendiente | H7: 0
